Workbook
Name Prime_1: [1]Données!#REF!
Name Prime_2: [1]Données!#REF!
Name Prime_3: [1]Données!#REF!
Name Salaire_annuel: [1]Données!#REF!
Name Salaire_mensuel: [1]Données!#REF!

Sheet TDB
C1: TDB RH NADOR -12/25
C3: Turnover | E3: CDI | F3: ANAPEC | G3: % Encadrement | I3: Séniorité | K3: Recrutement | M3: Depart
C4: ='Pyramide age'!AR16 -> 0.15769231 | E4: =COUNTIF(EFFECTIF!O:O,E3) -> 139 | F4: =COUNTIF(EFFECTIF!O:O,F3) -> 7 | G4: ='Pyramide age'!AR20 -> 0.063291139 | I4: =AVERAGE(EFFECTIF!S2:S159) -> 13.736287 | K4: =mouvement!F33 -> 29 | M4: =mouvement!F49 -> 12
J27: Homme | L27: Femme | N27: Total
I28: AM | J28: =COUNTIFS(EFFECTIF!R:R,1,EFFECTIF!K:K,1,EFFECTIF!E:E,"Maitrise") -> 49 | L28: =COUNTIFS(EFFECTIF!R:R,2,EFFECTIF!K:K,1,EFFECTIF!E:E,"Maitrise") -> 6 | N28: =J28+L28 -> 55
I29: EMPLOYE | J29: =COUNTIFS(EFFECTIF!R:R,1,EFFECTIF!K:K,1,EFFECTIF!E:E,"Employé") -> 81 | L29: =COUNTIFS(EFFECTIF!R:R,2,EFFECTIF!K:K,1,EFFECTIF!E:E,"Employé") -> 0 | N29: =J29+L29 -> 81
I30: CADRE | J30: =COUNTIFS(EFFECTIF!R:R,1,EFFECTIF!K:K,1,EFFECTIF!E:E,"Cadre") -> 10 | L30: =COUNTIFS(EFFECTIF!R:R,2,EFFECTIF!K:K,1,EFFECTIF!E:E,"Cadre") -> 0 | N30: =J30+L30 -> 10
I31: Total | J31: =SUM(J28:K30) -> 140 | L31: =SUM(L28:M30) -> 6 | N31: =J31+L31 -> 146

Sheet EFFECTIF
A1: MATRICULE | B1: NOM | C1: PRENOM | D1: Lieu de travail | E1: Collège | F1: DEB_CONTRAT | G1: C cout | H1: Date de naissance | I1: Date retraite | J1: Date de départ | K1: Toujours à la sonasid la sonasid | L1: Motif | M1: Âge | N1: Sexe | O1: Type contrat | P1: affectation | Q1: pyramide age | R1: H/F | S1: ANCIENNTE | T1: pyramide ANCIENNTE
A2: 239 | B2: BELHASSANI | C2: OMAR | D2: Nador | E2: Maitrise | F2: 31348 | G2: "2MAI10 | H2: 24093 | I2: =H2+(365.25*60) -> 46008 | K2: 1 | M2: =K2*(DATEDIF(H2,TODAY(),"m")/12) -> 60.5 | N2: Mr | O2: CDI | P2: NADOR | Q2: =IF(K2=1,IF(Paramètres!$E$9,IF(M2<Paramètres!$B$13,Paramètres!$C$13,IF(M2<Paramètres!$B$14,Paramètres!$C$14,IF(M2<Paramètres!$B$15,Paramètres!$C$15,IF(M2<Paramètres!$B$16,Paramètres!$C$16,IF(M2<Paramètres!$B$17,Paramètres!$C$17,IF(M2<Paramètres!$B$18,Paramètres!$C$18,IF(M2<Paramètres!$B$19,Paramètres!$C$19,IF(M2<Paramètres!$B$20,Paramètres!$C$20,IF(M2<Paramètres!$B$21,Paramètres!$C$21,Paramètres!$C$22))))))))),M2),"") -> De 60 à 64 ans | R2: =+IF(N2="Mr",1,2) -> 1 | S2: =DATEDIF(F2,TODAY(),"m")/12 -> 40.666667 | T2: =IF(K2=1,IF(Paramètres!$E$25,IF(S2<Paramètres!$B$29,Paramètres!$C$29,IF(S2<Paramètres!$B$30,Paramètres!$C$30,IF(S2<Paramètres!$B$31,Paramètres!$C$31,IF(S2<Paramètres!$B$32,Paramètres!$C$32,IF(S2<Paramètres!$B$33,Paramètres!$C$33,IF(S2<Paramètres!$B$34,Paramètres!$C$34,IF(S2<Paramètres!$B$35,Paramètres!$C$35,IF(S2<Paramètres!$B$36,Paramètres!$C$36,IF(S2<Paramètres!$B$37,Paramètres!$C$37,Paramètres!$C$38))))))))),[3]Données!P453),"") -> De 40 à 49 ans
A3: 302 | B3: CHOUA | C3: MOHAMED | D3: Nador | E3: Maitrise | F3: 32470 | G3: "2NAD01 | H3: 23923 | I3: =H3+(365.25*60) -> 45838 | J3: 45838 | K3: 0 | L3: Retraite | M3: =K3*(DATEDIF(H3,TODAY(),"m")/12) -> 0 | N3: Mr | P3: NADOR | Q3: =IF(K3=1,IF(Paramètres!$E$9,IF(M3<Paramètres!$B$13,Paramètres!$C$13,IF(M3<Paramètres!$B$14,Paramètres!$C$14,IF(M3<Paramètres!$B$15,Paramètres!$C$15,IF(M3<Paramètres!$B$16,Paramètres!$C$16,IF(M3<Paramètres!$B$17,Paramètres!$C$17,IF(M3<Paramètres!$B$18,Paramètres!$C$18,IF(M3<Paramètres!$B$19,Paramètres!$C$19,IF(M3<Paramètres!$B$20,Paramètres!$C$20,IF(M3<Paramètres!$B$21,Paramètres!$C$21,Paramètres!$C$22))))))))),M3),"") | R3: =+IF(N3="Mr",1,2) -> 1 | S3: =K3*(DATEDIF(F3,TODAY(),"m")/12) -> 0 | T3: =IF(K3=1,IF(Paramètres!$E$25,IF(S3<Paramètres!$B$29,Paramètres!$C$29,IF(S3<Paramètres!$B$30,Paramètres!$C$30,IF(S3<Paramètres!$B$31,Paramètres!$C$31,IF(S3<Paramètres!$B$32,Paramètres!$C$32,IF(S3<Paramètres!$B$33,Paramètres!$C$33,IF(S3<Paramètres!$B$34,Paramètres!$C$34,IF(S3<Paramètres!$B$35,Paramètres!$C$35,IF(S3<Paramètres!$B$36,Paramètres!$C$36,IF(S3<Paramètres!$B$37,Paramètres!$C$37,Paramètres!$C$38))))))))),[3]Données!P600),"")
A4: 309 | B4: AMDARI | C4: MUSTAPHA | D4: Nador | E4: Maitrise | F4: 32539 | G4: "2FIB01 | H4: 25653 | I4: =H4+(365.25*60) -> 47568 | K4: 1 | M4: =K4*(DATEDIF(H4,TODAY(),"m")/12) -> 56.25 | N4: Mr | O4: CDI | P4: NADOR | Q4: =IF(K4=1,IF(Paramètres!$E$9,IF(M4<Paramètres!$B$13,Paramètres!$C$13,IF(M4<Paramètres!$B$14,Paramètres!$C$14,IF(M4<Paramètres!$B$15,Paramètres!$C$15,IF(M4<Paramètres!$B$16,Paramètres!$C$16,IF(M4<Paramètres!$B$17,Paramètres!$C$17,IF(M4<Paramètres!$B$18,Paramètres!$C$18,IF(M4<Paramètres!$B$19,Paramètres!$C$19,IF(M4<Paramètres!$B$20,Paramètres!$C$20,IF(M4<Paramètres!$B$21,Paramètres!$C$21,Paramètres!$C$22))))))))),M4),"") -> De 55 à 59 ans | R4: =+IF(N4="Mr",1,2) -> 1 | S4: =DATEDIF(F4,TODAY(),"m")/12 -> 37.416667 | T4: =IF(K4=1,IF(Paramètres!$E$25,IF(S4<Paramètres!$B$29,Paramètres!$C$29,IF(S4<Paramètres!$B$30,Paramètres!$C$30,IF(S4<Paramètres!$B$31,Paramètres!$C$31,IF(S4<Paramètres!$B$32,Paramètres!$C$32,IF(S4<Paramètres!$B$33,Paramètres!$C$33,IF(S4<Paramètres!$B$34,Paramètres!$C$34,IF(S4<Paramètres!$B$35,Paramètres!$C$35,IF(S4<Paramètres!$B$36,Paramètres!$C$36,IF(S4<Paramètres!$B$37,Paramètres!$C$37,Paramètres!$C$38))))))))),[3]Données!P454),"") -> De 35 à 39 ans
A5: 324 | B5: EL KADAOUI | C5: HASSAN | D5: Nador | E5: Maitrise | F5: 32822 | G5: "2PRO05 | H5: 23892 | I5: =H5+(365.25*60) -> 45807 | J5: 45807 | K5: 0 | L5: Retraite | M5: =K5*(DATEDIF(H5,TODAY(),"m")/12) -> 0 | N5: Mr | P5: NADOR | Q5: =IF(K5=1,IF(Paramètres!$E$9,IF(M5<Paramètres!$B$13,Paramètres!$C$13,IF(M5<Paramètres!$B$14,Paramètres!$C$14,IF(M5<Paramètres!$B$15,Paramètres!$C$15,IF(M5<Paramètres!$B$16,Paramètres!$C$16,IF(M5<Paramètres!$B$17,Paramètres!$C$17,IF(M5<Paramètres!$B$18,Paramètres!$C$18,IF(M5<Paramètres!$B$19,Paramètres!$C$19,IF(M5<Paramètres!$B$20,Paramètres!$C$20,IF(M5<Paramètres!$B$21,Paramètres!$C$21,Paramètres!$C$22))))))))),M5),"") | R5: =+IF(N5="Mr",1,2) -> 1 | S5: =K5*(DATEDIF(F5,TODAY(),"m")/12) -> 0 | T5: =IF(K5=1,IF(Paramètres!$E$25,IF(S5<Paramètres!$B$29,Paramètres!$C$29,IF(S5<Paramètres!$B$30,Paramètres!$C$30,IF(S5<Paramètres!$B$31,Paramètres!$C$31,IF(S5<Paramètres!$B$32,Paramètres!$C$32,IF(S5<Paramètres!$B$33,Paramètres!$C$33,IF(S5<Paramètres!$B$34,Paramètres!$C$34,IF(S5<Paramètres!$B$35,Paramètres!$C$35,IF(S5<Paramètres!$B$36,Paramètres!$C$36,IF(S5<Paramètres!$B$37,Paramètres!$C$37,Paramètres!$C$38))))))))),[3]Données!P601),"")
A6: 325 | B6: LAMRINI | C6: MIMOUN | D6: Nador | E6: Maitrise | F6: 32822 | G6: "2PRO02 | H6: 24277 | I6: =H6+(365.25*60) -> 46192 | K6: 1 | M6: =K6*(DATEDIF(H6,TODAY(),"m")/12) -> 60 | N6: Mr | O6: CDI | P6: NADOR | Q6: =IF(K6=1,IF(Paramètres!$E$9,IF(M6<Paramètres!$B$13,Paramètres!$C$13,IF(M6<Paramètres!$B$14,Paramètres!$C$14,IF(M6<Paramètres!$B$15,Paramètres!$C$15,IF(M6<Paramètres!$B$16,Paramètres!$C$16,IF(M6<Paramètres!$B$17,Paramètres!$C$17,IF(M6<Paramètres!$B$18,Paramètres!$C$18,IF(M6<Paramètres!$B$19,Paramètres!$C$19,IF(M6<Paramètres!$B$20,Paramètres!$C$20,IF(M6<Paramètres!$B$21,Paramètres!$C$21,Paramètres!$C$22))))))))),M6),"") -> De 60 à 64 ans | R6: =+IF(N6="Mr",1,2) -> 1 | S6: =DATEDIF(F6,TODAY(),"m")/12 -> 36.583333 | T6: =IF(K6=1,IF(Paramètres!$E$25,IF(S6<Paramètres!$B$29,Paramètres!$C$29,IF(S6<Paramètres!$B$30,Paramètres!$C$30,IF(S6<Paramètres!$B$31,Paramètres!$C$31,IF(S6<Paramètres!$B$32,Paramètres!$C$32,IF(S6<Paramètres!$B$33,Paramètres!$C$33,IF(S6<Paramètres!$B$34,Paramètres!$C$34,IF(S6<Paramètres!$B$35,Paramètres!$C$35,IF(S6<Paramètres!$B$36,Paramètres!$C$36,IF(S6<Paramètres!$B$37,Paramètres!$C$37,Paramètres!$C$38))))))))),[3]Données!P455),"") -> De 35 à 39 ans
A7: 332 | B7: RHANJATI | C7: MOHAMED | D7: Nador | E7: Employé | F7: 32898 | G7: "2PRO06 | H7: 26218 | I7: =H7+(365.25*60) -> 48133 | K7: 1 | M7: =K7*(DATEDIF(H7,TODAY(),"m")/12) -> 54.666667 | N7: Mr | O7: CDI | P7: NADOR | Q7: =IF(K7=1,IF(Paramètres!$E$9,IF(M7<Paramètres!$B$13,Paramètres!$C$13,IF(M7<Paramètres!$B$14,Paramètres!$C$14,IF(M7<Paramètres!$B$15,Paramètres!$C$15,IF(M7<Paramètres!$B$16,Paramètres!$C$16,IF(M7<Paramètres!$B$17,Paramètres!$C$17,IF(M7<Paramètres!$B$18,Paramètres!$C$18,IF(M7<Paramètres!$B$19,Paramètres!$C$19,IF(M7<Paramètres!$B$20,Paramètres!$C$20,IF(M7<Paramètres!$B$21,Paramètres!$C$21,Paramètres!$C$22))))))))),M7),"") -> De 50 à 54 ans | R7: =+IF(N7="Mr",1,2) -> 1 | S7: =K7*(DATEDIF(F7,TODAY(),"m")/12) -> 36.416667 | T7: =IF(K7=1,IF(Paramètres!$E$25,IF(S7<Paramètres!$B$29,Paramètres!$C$29,IF(S7<Paramètres!$B$30,Paramètres!$C$30,IF(S7<Paramètres!$B$31,Paramètres!$C$31,IF(S7<Paramètres!$B$32,Paramètres!$C$32,IF(S7<Paramètres!$B$33,Paramètres!$C$33,IF(S7<Paramètres!$B$34,Paramètres!$C$34,IF(S7<Paramètres!$B$35,Paramètres!$C$35,IF(S7<Paramètres!$B$36,Paramètres!$C$36,IF(S7<Paramètres!$B$37,Paramètres!$C$37,Paramètres!$C$38))))))))),[3]Données!P456),"") -> De 35 à 39 ans
A8: 333 | B8: BOUAAMAMA | C8: BOUCHTA | D8: Nador | E8: Employé | F8: 32905 | G8: "2PRO02 | H8: 25435 | I8: =H8+(365.25*60) -> 47350 | K8: 1 | M8: =K8*(DATEDIF(H8,TODAY(),"m")/12) -> 56.833333 | N8: Mr | O8: CDI | P8: NADOR | Q8: =IF(K8=1,IF(Paramètres!$E$9,IF(M8<Paramètres!$B$13,Paramètres!$C$13,IF(M8<Paramètres!$B$14,Paramètres!$C$14,IF(M8<Paramètres!$B$15,Paramètres!$C$15,IF(M8<Paramètres!$B$16,Paramètres!$C$16,IF(M8<Paramètres!$B$17,Paramètres!$C$17,IF(M8<Paramètres!$B$18,Paramètres!$C$18,IF(M8<Paramètres!$B$19,Paramètres!$C$19,IF(M8<Paramètres!$B$20,Paramètres!$C$20,IF(M8<Paramètres!$B$21,Paramètres!$C$21,Paramètres!$C$22))))))))),M8),"") -> De 55 à 59 ans | R8: =+IF(N8="Mr",1,2) -> 1 | S8: =K8*(DATEDIF(F8,TODAY(),"m")/12) -> 36.416667 | T8: =IF(K8=1,IF(Paramètres!$E$25,IF(S8<Paramètres!$B$29,Paramètres!$C$29,IF(S8<Paramètres!$B$30,Paramètres!$C$30,IF(S8<Paramètres!$B$31,Paramètres!$C$31,IF(S8<Paramètres!$B$32,Paramètres!$C$32,IF(S8<Paramètres!$B$33,Paramètres!$C$33,IF(S8<Paramètres!$B$34,Paramètres!$C$34,IF(S8<Paramètres!$B$35,Paramètres!$C$35,IF(S8<Paramètres!$B$36,Paramètres!$C$36,IF(S8<Paramètres!$B$37,Paramètres!$C$37,Paramètres!$C$38))))))))),[3]Données!P457),"") -> De 35 à 39 ans
A9: 338 | B9: AKALAI | C9: MIMOUN | D9: Nador | E9: Maitrise | F9: 33001 | G9: "2PRO06 | H9: 24284 | I9: =H9+(365.25*60) -> 46199 | K9: 1 | M9: =K9*(DATEDIF(H9,TODAY(),"m")/12) -> 60 | N9: Mr | O9: CDI | P9: NADOR | Q9: =IF(K9=1,IF(Paramètres!$E$9,IF(M9<Paramètres!$B$13,Paramètres!$C$13,IF(M9<Paramètres!$B$14,Paramètres!$C$14,IF(M9<Paramètres!$B$15,Paramètres!$C$15,IF(M9<Paramètres!$B$16,Paramètres!$C$16,IF(M9<Paramètres!$B$17,Paramètres!$C$17,IF(M9<Paramètres!$B$18,Paramètres!$C$18,IF(M9<Paramètres!$B$19,Paramètres!$C$19,IF(M9<Paramètres!$B$20,Paramètres!$C$20,IF(M9<Paramètres!$B$21,Paramètres!$C$21,Paramètres!$C$22))))))))),M9),"") -> De 60 à 64 ans | R9: =+IF(N9="Mr",1,2) -> 1 | S9: =K9*(DATEDIF(F9,TODAY(),"m")/12) -> 36.083333 | T9: =IF(K9=1,IF(Paramètres!$E$25,IF(S9<Paramètres!$B$29,Paramètres!$C$29,IF(S9<Paramètres!$B$30,Paramètres!$C$30,IF(S9<Paramètres!$B$31,Paramètres!$C$31,IF(S9<Paramètres!$B$32,Paramètres!$C$32,IF(S9<Paramètres!$B$33,Paramètres!$C$33,IF(S9<Paramètres!$B$34,Paramètres!$C$34,IF(S9<Paramètres!$B$35,Paramètres!$C$35,IF(S9<Paramètres!$B$36,Paramètres!$C$36,IF(S9<Paramètres!$B$37,Paramètres!$C$37,Paramètres!$C$38))))))))),[3]Données!P458),"") -> De 35 à 39 ans
A10: 341 | B10: ALAOUI | C10: MOULAY MUSTAPHA | D10: Nador | E10: Employé | F10: 33072 | G10: "2PRO02 | H10: 24439 | I10: =H10+(365.25*60) -> 46354 | K10: 1 | M10: =K10*(DATEDIF(H10,TODAY(),"m")/12) -> 59.583333 | N10: Mr | O10: CDI | P10: NADOR | Q10: =IF(K10=1,IF(Paramètres!$E$9,IF(M10<Paramètres!$B$13,Paramètres!$C$13,IF(M10<Paramètres!$B$14,Paramètres!$C$14,IF(M10<Paramètres!$B$15,Paramètres!$C$15,IF(M10<Paramètres!$B$16,Paramètres!$C$16,IF(M10<Paramètres!$B$17,Paramètres!$C$17,IF(M10<Paramètres!$B$18,Paramètres!$C$18,IF(M10<Paramètres!$B$19,Paramètres!$C$19,IF(M10<Paramètres!$B$20,Paramètres!$C$20,IF(M10<Paramètres!$B$21,Paramètres!$C$21,Paramètres!$C$22))))))))),M10),"") -> De 55 à 59 ans | R10: =+IF(N10="Mr",1,2) -> 1 | S10: =K10*(DATEDIF(F10,TODAY(),"m")/12) -> 35.916667 | T10: =IF(K10=1,IF(Paramètres!$E$25,IF(S10<Paramètres!$B$29,Paramètres!$C$29,IF(S10<Paramètres!$B$30,Paramètres!$C$30,IF(S10<Paramètres!$B$31,Paramètres!$C$31,IF(S10<Paramètres!$B$32,Paramètres!$C$32,IF(S10<Paramètres!$B$33,Paramètres!$C$33,IF(S10<Paramètres!$B$34,Paramètres!$C$34,IF(S10<Paramètres!$B$35,Paramètres!$C$35,IF(S10<Paramètres!$B$36,Paramètres!$C$36,IF(S10<Paramètres!$B$37,Paramètres!$C$37,Paramètres!$C$38))))))))),[3]Données!P459),"") -> De 35 à 39 ans
A11: 344 | B11: EL AMMARI | C11: MOHAMED | D11: Nador | E11: Maitrise | F11: 33085 | G11: "2FIB01 | H11: 24038 | I11: =H11+(365.25*60) -> 45953 | J11: 45953 | K11: 0 | L11: Retraite | M11: =K11*(DATEDIF(H11,TODAY(),"m")/12) -> 0 | N11: Mr | P11: NADOR | Q11: =IF(K11=1,IF(Paramètres!$E$9,IF(M11<Paramètres!$B$13,Paramètres!$C$13,IF(M11<Paramètres!$B$14,Paramètres!$C$14,IF(M11<Paramètres!$B$15,Paramètres!$C$15,IF(M11<Paramètres!$B$16,Paramètres!$C$16,IF(M11<Paramètres!$B$17,Paramètres!$C$17,IF(M11<Paramètres!$B$18,Paramètres!$C$18,IF(M11<Paramètres!$B$19,Paramètres!$C$19,IF(M11<Paramètres!$B$20,Paramètres!$C$20,IF(M11<Paramètres!$B$21,Paramètres!$C$21,Paramètres!$C$22))))))))),M11),"") | R11: =+IF(N11="Mr",1,2) -> 1 | S11: =K11*(DATEDIF(F11,TODAY(),"m")/12) -> 0 | T11: =IF(K11=1,IF(Paramètres!$E$25,IF(S11<Paramètres!$B$29,Paramètres!$C$29,IF(S11<Paramètres!$B$30,Paramètres!$C$30,IF(S11<Paramètres!$B$31,Paramètres!$C$31,IF(S11<Paramètres!$B$32,Paramètres!$C$32,IF(S11<Paramètres!$B$33,Paramètres!$C$33,IF(S11<Paramètres!$B$34,Paramètres!$C$34,IF(S11<Paramètres!$B$35,Paramètres!$C$35,IF(S11<Paramètres!$B$36,Paramètres!$C$36,IF(S11<Paramètres!$B$37,Paramètres!$C$37,Paramètres!$C$38))))))))),[3]Données!P460),"")
A12: 347 | B12: AOUANE | C12: ABDENBI | D12: Nador | E12: Maitrise | F12: 33148 | G12: "2MAI09 | H12: 24867 | I12: =H12+(365.25*60) -> 46782 | K12: 1 | M12: =K12*(DATEDIF(H12,TODAY(),"m")/12) -> 58.416667 | N12: Mr | O12: CDI | P12: NADOR | Q12: =IF(K12=1,IF(Paramètres!$E$9,IF(M12<Paramètres!$B$13,Paramètres!$C$13,IF(M12<Paramètres!$B$14,Paramètres!$C$14,IF(M12<Paramètres!$B$15,Paramètres!$C$15,IF(M12<Paramètres!$B$16,Paramètres!$C$16,IF(M12<Paramètres!$B$17,Paramètres!$C$17,IF(M12<Paramètres!$B$18,Paramètres!$C$18,IF(M12<Paramètres!$B$19,Paramètres!$C$19,IF(M12<Paramètres!$B$20,Paramètres!$C$20,IF(M12<Paramètres!$B$21,Paramètres!$C$21,Paramètres!$C$22))))))))),M12),"") -> De 55 à 59 ans | R12: =+IF(N12="Mr",1,2) -> 1 | S12: =K12*(DATEDIF(F12,TODAY(),"m")/12) -> 35.75 | T12: =IF(K12=1,IF(Paramètres!$E$25,IF(S12<Paramètres!$B$29,Paramètres!$C$29,IF(S12<Paramètres!$B$30,Paramètres!$C$30,IF(S12<Paramètres!$B$31,Paramètres!$C$31,IF(S12<Paramètres!$B$32,Paramètres!$C$32,IF(S12<Paramètres!$B$33,Paramètres!$C$33,IF(S12<Paramètres!$B$34,Paramètres!$C$34,IF(S12<Paramètres!$B$35,Paramètres!$C$35,IF(S12<Paramètres!$B$36,Paramètres!$C$36,IF(S12<Paramètres!$B$37,Paramètres!$C$37,Paramètres!$C$38))))))))),[3]Données!P461),"") -> De 35 à 39 ans
A13: 354 | B13: EL IDRISSI | C13: NOUREDDINE | D13: Nador | E13: Employé | F13: 33233 | G13: "2MAG01 | H13: 23867 | I13: =H13+(365.25*60) -> 45782 | J13: 45782 | K13: 0 | L13: Retraite | M13: =K13*(DATEDIF(H13,TODAY(),"m")/12) -> 0 | N13: Mr | P13: NADOR | Q13: =IF(K13=1,IF(Paramètres!$E$9,IF(M13<Paramètres!$B$13,Paramètres!$C$13,IF(M13<Paramètres!$B$14,Paramètres!$C$14,IF(M13<Paramètres!$B$15,Paramètres!$C$15,IF(M13<Paramètres!$B$16,Paramètres!$C$16,IF(M13<Paramètres!$B$17,Paramètres!$C$17,IF(M13<Paramètres!$B$18,Paramètres!$C$18,IF(M13<Paramètres!$B$19,Paramètres!$C$19,IF(M13<Paramètres!$B$20,Paramètres!$C$20,IF(M13<Paramètres!$B$21,Paramètres!$C$21,Paramètres!$C$22))))))))),M13),"") | R13: =+IF(N13="Mr",1,2) -> 1 | S13: =K13*(DATEDIF(F13,TODAY(),"m")/12) -> 0 | T13: =IF(K13=1,IF(Paramètres!$E$25,IF(S13<Paramètres!$B$29,Paramètres!$C$29,IF(S13<Paramètres!$B$30,Paramètres!$C$30,IF(S13<Paramètres!$B$31,Paramètres!$C$31,IF(S13<Paramètres!$B$32,Paramètres!$C$32,IF(S13<Paramètres!$B$33,Paramètres!$C$33,IF(S13<Paramètres!$B$34,Paramètres!$C$34,IF(S13<Paramètres!$B$35,Paramètres!$C$35,IF(S13<Paramètres!$B$36,Paramètres!$C$36,IF(S13<Paramètres!$B$37,Paramètres!$C$37,Paramètres!$C$38))))))))),[3]Données!P602),"")
A14: 355 | B14: ALJI | C14: MAHMOUD | D14: Nador | E14: Maitrise | F14: 33246 | G14: "2MAI01 | H14: 24324 | I14: =H14+(365.25*60) -> 46239 | K14: 1 | M14: =K14*(DATEDIF(H14,TODAY(),"m")/12) -> 59.916667 | N14: Mr | O14: CDI | P14: NADOR | Q14: =IF(K14=1,IF(Paramètres!$E$9,IF(M14<Paramètres!$B$13,Paramètres!$C$13,IF(M14<Paramètres!$B$14,Paramètres!$C$14,IF(M14<Paramètres!$B$15,Paramètres!$C$15,IF(M14<Paramètres!$B$16,Paramètres!$C$16,IF(M14<Paramètres!$B$17,Paramètres!$C$17,IF(M14<Paramètres!$B$18,Paramètres!$C$18,IF(M14<Paramètres!$B$19,Paramètres!$C$19,IF(M14<Paramètres!$B$20,Paramètres!$C$20,IF(M14<Paramètres!$B$21,Paramètres!$C$21,Paramètres!$C$22))))))))),M14),"") -> De 55 à 59 ans | R14: =+IF(N14="Mr",1,2) -> 1 | S14: =K14*(DATEDIF(F14,TODAY(),"m")/12) -> 35.416667 | T14: =IF(K14=1,IF(Paramètres!$E$25,IF(S14<Paramètres!$B$29,Paramètres!$C$29,IF(S14<Paramètres!$B$30,Paramètres!$C$30,IF(S14<Paramètres!$B$31,Paramètres!$C$31,IF(S14<Paramètres!$B$32,Paramètres!$C$32,IF(S14<Paramètres!$B$33,Paramètres!$C$33,IF(S14<Paramètres!$B$34,Paramètres!$C$34,IF(S14<Paramètres!$B$35,Paramètres!$C$35,IF(S14<Paramètres!$B$36,Paramètres!$C$36,IF(S14<Paramètres!$B$37,Paramètres!$C$37,Paramètres!$C$38))))))))),[3]Données!P462),"") -> De 35 à 39 ans
A15: 356 | B15: IATISSAMI | C15: MUSTAPHA | D15: Nador | E15: Maitrise | F15: 33287 | G15: "2PRO06 | H15: 25263 | I15: =H15+(365.25*60) -> 47178 | K15: 1 | M15: =K15*(DATEDIF(H15,TODAY(),"m")/12) -> 57.333333 | N15: Mr | O15: CDI | P15: NADOR | Q15: =IF(K15=1,IF(Paramètres!$E$9,IF(M15<Paramètres!$B$13,Paramètres!$C$13,IF(M15<Paramètres!$B$14,Paramètres!$C$14,IF(M15<Paramètres!$B$15,Paramètres!$C$15,IF(M15<Paramètres!$B$16,Paramètres!$C$16,IF(M15<Paramètres!$B$17,Paramètres!$C$17,IF(M15<Paramètres!$B$18,Paramètres!$C$18,IF(M15<Paramètres!$B$19,Paramètres!$C$19,IF(M15<Paramètres!$B$20,Paramètres!$C$20,IF(M15<Paramètres!$B$21,Paramètres!$C$21,Paramètres!$C$22))))))))),M15),"") -> De 55 à 59 ans | R15: =+IF(N15="Mr",1,2) -> 1 | S15: =K15*(DATEDIF(F15,TODAY(),"m")/12) -> 35.333333 | T15: =IF(K15=1,IF(Paramètres!$E$25,IF(S15<Paramètres!$B$29,Paramètres!$C$29,IF(S15<Paramètres!$B$30,Paramètres!$C$30,IF(S15<Paramètres!$B$31,Paramètres!$C$31,IF(S15<Paramètres!$B$32,Paramètres!$C$32,IF(S15<Paramètres!$B$33,Paramètres!$C$33,IF(S15<Paramètres!$B$34,Paramètres!$C$34,IF(S15<Paramètres!$B$35,Paramètres!$C$35,IF(S15<Paramètres!$B$36,Paramètres!$C$36,IF(S15<Paramètres!$B$37,Paramètres!$C$37,Paramètres!$C$38))))))))),[3]Données!P463),"") -> De 35 à 39 ans
A16: 357 | B16: MOUNIB | C16: ABDELATI | D16: Nador | E16: Maitrise | F16: 33288 | G16: "2MAI02 | H16: 24627 | I16: =H16+(365.25*60) -> 46542 | K16: 1 | M16: =K16*(DATEDIF(H16,TODAY(),"m")/12) -> 59.083333 | N16: Mr | O16: CDI | P16: NADOR | Q16: =IF(K16=1,IF(Paramètres!$E$9,IF(M16<Paramètres!$B$13,Paramètres!$C$13,IF(M16<Paramètres!$B$14,Paramètres!$C$14,IF(M16<Paramètres!$B$15,Paramètres!$C$15,IF(M16<Paramètres!$B$16,Paramètres!$C$16,IF(M16<Paramètres!$B$17,Paramètres!$C$17,IF(M16<Paramètres!$B$18,Paramètres!$C$18,IF(M16<Paramètres!$B$19,Paramètres!$C$19,IF(M16<Paramètres!$B$20,Paramètres!$C$20,IF(M16<Paramètres!$B$21,Paramètres!$C$21,Paramètres!$C$22))))))))),M16),"") -> De 55 à 59 ans | R16: =+IF(N16="Mr",1,2) -> 1 | S16: =K16*(DATEDIF(F16,TODAY(),"m")/12) -> 35.333333 | T16: =IF(K16=1,IF(Paramètres!$E$25,IF(S16<Paramètres!$B$29,Paramètres!$C$29,IF(S16<Paramètres!$B$30,Paramètres!$C$30,IF(S16<Paramètres!$B$31,Paramètres!$C$31,IF(S16<Paramètres!$B$32,Paramètres!$C$32,IF(S16<Paramètres!$B$33,Paramètres!$C$33,IF(S16<Paramètres!$B$34,Paramètres!$C$34,IF(S16<Paramètres!$B$35,Paramètres!$C$35,IF(S16<Paramètres!$B$36,Paramètres!$C$36,IF(S16<Paramètres!$B$37,Paramètres!$C$37,Paramètres!$C$38))))))))),[3]Données!P464),"") -> De 35 à 39 ans
A17: 363 | B17: EL HAFHAFI | C17: ABDELAZIZ | D17: Nador | E17: Employé | F17: 33525 | G17: "2PRO06 | H17: 23911 | I17: =H17+(365.25*60) -> 45826 | J17: 45826 | K17: 0 | L17: Retraite | M17: =K17*(DATEDIF(H17,TODAY(),"m")/12) -> 0 | N17: Mr | P17: NADOR | Q17: =IF(K17=1,IF(Paramètres!$E$9,IF(M17<Paramètres!$B$13,Paramètres!$C$13,IF(M17<Paramètres!$B$14,Paramètres!$C$14,IF(M17<Paramètres!$B$15,Paramètres!$C$15,IF(M17<Paramètres!$B$16,Paramètres!$C$16,IF(M17<Paramètres!$B$17,Paramètres!$C$17,IF(M17<Paramètres!$B$18,Paramètres!$C$18,IF(M17<Paramètres!$B$19,Paramètres!$C$19,IF(M17<Paramètres!$B$20,Paramètres!$C$20,IF(M17<Paramètres!$B$21,Paramètres!$C$21,Paramètres!$C$22))))))))),M17),"") | R17: =+IF(N17="Mr",1,2) -> 1 | S17: =K17*(DATEDIF(F17,TODAY(),"m")/12) -> 0 | T17: =IF(K17=1,IF(Paramètres!$E$25,IF(S17<Paramètres!$B$29,Paramètres!$C$29,IF(S17<Paramètres!$B$30,Paramètres!$C$30,IF(S17<Paramètres!$B$31,Paramètres!$C$31,IF(S17<Paramètres!$B$32,Paramètres!$C$32,IF(S17<Paramètres!$B$33,Paramètres!$C$33,IF(S17<Paramètres!$B$34,Paramètres!$C$34,IF(S17<Paramètres!$B$35,Paramètres!$C$35,IF(S17<Paramètres!$B$36,Paramètres!$C$36,IF(S17<Paramètres!$B$37,Paramètres!$C$37,Paramètres!$C$38))))))))),[3]Données!P603),"")
A18: 364 | B18: JAOUAL | C18: SAID | D18: Nador | E18: Employé | F18: 33589 | G18: "2PRO05 | H18: 25498 | I18: =H18+(365.25*60) -> 47413 | K18: 1 | M18: =K18*(DATEDIF(H18,TODAY(),"m")/12) -> 56.666667 | N18: Mr | O18: CDI | P18: NADOR | Q18: =IF(K18=1,IF(Paramètres!$E$9,IF(M18<Paramètres!$B$13,Paramètres!$C$13,IF(M18<Paramètres!$B$14,Paramètres!$C$14,IF(M18<Paramètres!$B$15,Paramètres!$C$15,IF(M18<Paramètres!$B$16,Paramètres!$C$16,IF(M18<Paramètres!$B$17,Paramètres!$C$17,IF(M18<Paramètres!$B$18,Paramètres!$C$18,IF(M18<Paramètres!$B$19,Paramètres!$C$19,IF(M18<Paramètres!$B$20,Paramètres!$C$20,IF(M18<Paramètres!$B$21,Paramètres!$C$21,Paramètres!$C$22))))))))),M18),"") -> De 55 à 59 ans | R18: =+IF(N18="Mr",1,2) -> 1 | S18: =K18*(DATEDIF(F18,TODAY(),"m")/12) -> 34.5 | T18: =IF(K18=1,IF(Paramètres!$E$25,IF(S18<Paramètres!$B$29,Paramètres!$C$29,IF(S18<Paramètres!$B$30,Paramètres!$C$30,IF(S18<Paramètres!$B$31,Paramètres!$C$31,IF(S18<Paramètres!$B$32,Paramètres!$C$32,IF(S18<Paramètres!$B$33,Paramètres!$C$33,IF(S18<Paramètres!$B$34,Paramètres!$C$34,IF(S18<Paramètres!$B$35,Paramètres!$C$35,IF(S18<Paramètres!$B$36,Paramètres!$C$36,IF(S18<Paramètres!$B$37,Paramètres!$C$37,Paramètres!$C$38))))))))),[3]Données!P465),"") -> De 30 à 34 ans
A19: 367 | B19: AKAAOUCH | C19: ALI | D19: Nador | E19: Maitrise | F19: 33637 | G19: "2MAI03 | H19: 25494 | I19: =H19+(365.25*60) -> 47409 | K19: 1 | M19: =K19*(DATEDIF(H19,TODAY(),"m")/12) -> 56.666667 | N19: Mr | O19: CDI | P19: NADOR | Q19: =IF(K19=1,IF(Paramètres!$E$9,IF(M19<Paramètres!$B$13,Paramètres!$C$13,IF(M19<Paramètres!$B$14,Paramètres!$C$14,IF(M19<Paramètres!$B$15,Paramètres!$C$15,IF(M19<Paramètres!$B$16,Paramètres!$C$16,IF(M19<Paramètres!$B$17,Paramètres!$C$17,IF(M19<Paramètres!$B$18,Paramètres!$C$18,IF(M19<Paramètres!$B$19,Paramètres!$C$19,IF(M19<Paramètres!$B$20,Paramètres!$C$20,IF(M19<Paramètres!$B$21,Paramètres!$C$21,Paramètres!$C$22))))))))),M19),"") -> De 55 à 59 ans | R19: =+IF(N19="Mr",1,2) -> 1 | S19: =K19*(DATEDIF(F19,TODAY(),"m")/12) -> 34.416667 | T19: =IF(K19=1,IF(Paramètres!$E$25,IF(S19<Paramètres!$B$29,Paramètres!$C$29,IF(S19<Paramètres!$B$30,Paramètres!$C$30,IF(S19<Paramètres!$B$31,Paramètres!$C$31,IF(S19<Paramètres!$B$32,Paramètres!$C$32,IF(S19<Paramètres!$B$33,Paramètres!$C$33,IF(S19<Paramètres!$B$34,Paramètres!$C$34,IF(S19<Paramètres!$B$35,Paramètres!$C$35,IF(S19<Paramètres!$B$36,Paramètres!$C$36,IF(S19<Paramètres!$B$37,Paramètres!$C$37,Paramètres!$C$38))))))))),[3]Données!P466),"") -> De 30 à 34 ans
A20: 368 | B20: OUCHNI | C20: HAMID | D20: Nador | E20: Maitrise | F20: 33637 | G20: "2PRO05 | H20: 25369 | I20: =H20+(365.25*60) -> 47284 | K20: 1 | M20: =K20*(DATEDIF(H20,TODAY(),"m")/12) -> 57 | N20: Mr | O20: CDI | P20: NADOR | Q20: =IF(K20=1,IF(Paramètres!$E$9,IF(M20<Paramètres!$B$13,Paramètres!$C$13,IF(M20<Paramètres!$B$14,Paramètres!$C$14,IF(M20<Paramètres!$B$15,Paramètres!$C$15,IF(M20<Paramètres!$B$16,Paramètres!$C$16,IF(M20<Paramètres!$B$17,Paramètres!$C$17,IF(M20<Paramètres!$B$18,Paramètres!$C$18,IF(M20<Paramètres!$B$19,Paramètres!$C$19,IF(M20<Paramètres!$B$20,Paramètres!$C$20,IF(M20<Paramètres!$B$21,Paramètres!$C$21,Paramètres!$C$22))))))))),M20),"") -> De 55 à 59 ans | R20: =+IF(N20="Mr",1,2) -> 1 | S20: =K20*(DATEDIF(F20,TODAY(),"m")/12) -> 34.416667 | T20: =IF(K20=1,IF(Paramètres!$E$25,IF(S20<Paramètres!$B$29,Paramètres!$C$29,IF(S20<Paramètres!$B$30,Paramètres!$C$30,IF(S20<Paramètres!$B$31,Paramètres!$C$31,IF(S20<Paramètres!$B$32,Paramètres!$C$32,IF(S20<Paramètres!$B$33,Paramètres!$C$33,IF(S20<Paramètres!$B$34,Paramètres!$C$34,IF(S20<Paramètres!$B$35,Paramètres!$C$35,IF(S20<Paramètres!$B$36,Paramètres!$C$36,IF(S20<Paramètres!$B$37,Paramètres!$C$37,Paramètres!$C$38))))))))),[3]Données!P467),"") -> De 30 à 34 ans
A21: 372 | B21: ABDAIM | C21: LAHOUCINE | D21: Nador | E21: Employé | F21: 33948 | G21: "2PRO08 | H21: 27210 | I21: =H21+(365.25*60) -> 49125 | K21: 1 | M21: =K21*(DATEDIF(H21,TODAY(),"m")/12) -> 52 | N21: Mr | O21: CDI | P21: NADOR | Q21: =IF(K21=1,IF(Paramètres!$E$9,IF(M21<Paramètres!$B$13,Paramètres!$C$13,IF(M21<Paramètres!$B$14,Paramètres!$C$14,IF(M21<Paramètres!$B$15,Paramètres!$C$15,IF(M21<Paramètres!$B$16,Paramètres!$C$16,IF(M21<Paramètres!$B$17,Paramètres!$C$17,IF(M21<Paramètres!$B$18,Paramètres!$C$18,IF(M21<Paramètres!$B$19,Paramètres!$C$19,IF(M21<Paramètres!$B$20,Paramètres!$C$20,IF(M21<Paramètres!$B$21,Paramètres!$C$21,Paramètres!$C$22))))))))),M21),"") -> De 50 à 54 ans | R21: =+IF(N21="Mr",1,2) -> 1 | S21: =K21*(DATEDIF(F21,TODAY(),"m")/12) -> 33.5 | T21: =IF(K21=1,IF(Paramètres!$E$25,IF(S21<Paramètres!$B$29,Paramètres!$C$29,IF(S21<Paramètres!$B$30,Paramètres!$C$30,IF(S21<Paramètres!$B$31,Paramètres!$C$31,IF(S21<Paramètres!$B$32,Paramètres!$C$32,IF(S21<Paramètres!$B$33,Paramètres!$C$33,IF(S21<Paramètres!$B$34,Paramètres!$C$34,IF(S21<Paramètres!$B$35,Paramètres!$C$35,IF(S21<Paramètres!$B$36,Paramètres!$C$36,IF(S21<Paramètres!$B$37,Paramètres!$C$37,Paramètres!$C$38))))))))),[3]Données!P468),"") -> De 30 à 34 ans
A22: 380 | B22: AZZAMMOURI | C22: LAARBI | D22: Nador | E22: Employé | F22: 33953 | G22: "2MAI10 | H22: 26109 | I22: =H22+(365.25*60) -> 48024 | K22: 1 | M22: =K22*(DATEDIF(H22,TODAY(),"m")/12) -> 55 | N22: Mr | O22: CDI | P22: NADOR | Q22: =IF(K22=1,IF(Paramètres!$E$9,IF(M22<Paramètres!$B$13,Paramètres!$C$13,IF(M22<Paramètres!$B$14,Paramètres!$C$14,IF(M22<Paramètres!$B$15,Paramètres!$C$15,IF(M22<Paramètres!$B$16,Paramètres!$C$16,IF(M22<Paramètres!$B$17,Paramètres!$C$17,IF(M22<Paramètres!$B$18,Paramètres!$C$18,IF(M22<Paramètres!$B$19,Paramètres!$C$19,IF(M22<Paramètres!$B$20,Paramètres!$C$20,IF(M22<Paramètres!$B$21,Paramètres!$C$21,Paramètres!$C$22))))))))),M22),"") -> De 55 à 59 ans | R22: =+IF(N22="Mr",1,2) -> 1 | S22: =K22*(DATEDIF(F22,TODAY(),"m")/12) -> 33.5 | T22: =IF(K22=1,IF(Paramètres!$E$25,IF(S22<Paramètres!$B$29,Paramètres!$C$29,IF(S22<Paramètres!$B$30,Paramètres!$C$30,IF(S22<Paramètres!$B$31,Paramètres!$C$31,IF(S22<Paramètres!$B$32,Paramètres!$C$32,IF(S22<Paramètres!$B$33,Paramètres!$C$33,IF(S22<Paramètres!$B$34,Paramètres!$C$34,IF(S22<Paramètres!$B$35,Paramètres!$C$35,IF(S22<Paramètres!$B$36,Paramètres!$C$36,IF(S22<Paramètres!$B$37,Paramètres!$C$37,Paramètres!$C$38))))))))),[3]Données!P469),"") -> De 30 à 34 ans
A23: 393 | B23: TALAA | C23: M'HAMMED | D23: Nador | E23: Maitrise | F23: 34554 | G23: "2PRO03 | H23: 25165 | I23: =H23+(365.25*60) -> 47080 | K23: 1 | M23: =K23*(DATEDIF(H23,TODAY(),"m")/12) -> 57.583333 | N23: Mr | O23: CDI | P23: NADOR | Q23: =IF(K23=1,IF(Paramètres!$E$9,IF(M23<Paramètres!$B$13,Paramètres!$C$13,IF(M23<Paramètres!$B$14,Paramètres!$C$14,IF(M23<Paramètres!$B$15,Paramètres!$C$15,IF(M23<Paramètres!$B$16,Paramètres!$C$16,IF(M23<Paramètres!$B$17,Paramètres!$C$17,IF(M23<Paramètres!$B$18,Paramètres!$C$18,IF(M23<Paramètres!$B$19,Paramètres!$C$19,IF(M23<Paramètres!$B$20,Paramètres!$C$20,IF(M23<Paramètres!$B$21,Paramètres!$C$21,Paramètres!$C$22))))))))),M23),"") -> De 55 à 59 ans | R23: =+IF(N23="Mr",1,2) -> 1 | S23: =K23*(DATEDIF(F23,TODAY(),"m")/12) -> 31.833333 | T23: =IF(K23=1,IF(Paramètres!$E$25,IF(S23<Paramètres!$B$29,Paramètres!$C$29,IF(S23<Paramètres!$B$30,Paramètres!$C$30,IF(S23<Paramètres!$B$31,Paramètres!$C$31,IF(S23<Paramètres!$B$32,Paramètres!$C$32,IF(S23<Paramètres!$B$33,Paramètres!$C$33,IF(S23<Paramètres!$B$34,Paramètres!$C$34,IF(S23<Paramètres!$B$35,Paramètres!$C$35,IF(S23<Paramètres!$B$36,Paramètres!$C$36,IF(S23<Paramètres!$B$37,Paramètres!$C$37,Paramètres!$C$38))))))))),[3]Données!P470),"") -> De 30 à 34 ans
A24: 455 | B24: TAHIRI | C24: ABDELKADER | D24: Nador | E24: Employé | F24: 35947 | G24: "2PRO05 | H24: 24750 | I24: =H24+(365.25*60) -> 46665 | K24: 1 | M24: =K24*(DATEDIF(H24,TODAY(),"m")/12) -> 58.75 | N24: Mr | O24: CDI | P24: NADOR | Q24: =IF(K24=1,IF(Paramètres!$E$9,IF(M24<Paramètres!$B$13,Paramètres!$C$13,IF(M24<Paramètres!$B$14,Paramètres!$C$14,IF(M24<Paramètres!$B$15,Paramètres!$C$15,IF(M24<Paramètres!$B$16,Paramètres!$C$16,IF(M24<Paramètres!$B$17,Paramètres!$C$17,IF(M24<Paramètres!$B$18,Paramètres!$C$18,IF(M24<Paramètres!$B$19,Paramètres!$C$19,IF(M24<Paramètres!$B$20,Paramètres!$C$20,IF(M24<Paramètres!$B$21,Paramètres!$C$21,Paramètres!$C$22))))))))),M24),"") -> De 55 à 59 ans | R24: =+IF(N24="Mr",1,2) -> 1 | S24: =K24*(DATEDIF(F24,TODAY(),"m")/12) -> 28.083333 | T24: =IF(K24=1,IF(Paramètres!$E$25,IF(S24<Paramètres!$B$29,Paramètres!$C$29,IF(S24<Paramètres!$B$30,Paramètres!$C$30,IF(S24<Paramètres!$B$31,Paramètres!$C$31,IF(S24<Paramètres!$B$32,Paramètres!$C$32,IF(S24<Paramètres!$B$33,Paramètres!$C$33,IF(S24<Paramètres!$B$34,Paramètres!$C$34,IF(S24<Paramètres!$B$35,Paramètres!$C$35,IF(S24<Paramètres!$B$36,Paramètres!$C$36,IF(S24<Paramètres!$B$37,Paramètres!$C$37,Paramètres!$C$38))))))))),[3]Données!P471),"") -> De 25 à 29 ans
A25: 456 | B25: ARRAISS | C25: ABDESLAM | D25: Nador | E25: Maitrise | F25: 35947 | G25: "2FIB01 | H25: 26344 | I25: =H25+(365.25*60) -> 48259 | K25: 1 | M25: =K25*(DATEDIF(H25,TODAY(),"m")/12) -> 54.333333 | N25: Mr | O25: CDI | P25: NADOR | Q25: =IF(K25=1,IF(Paramètres!$E$9,IF(M25<Paramètres!$B$13,Paramètres!$C$13,IF(M25<Paramètres!$B$14,Paramètres!$C$14,IF(M25<Paramètres!$B$15,Paramètres!$C$15,IF(M25<Paramètres!$B$16,Paramètres!$C$16,IF(M25<Paramètres!$B$17,Paramètres!$C$17,IF(M25<Paramètres!$B$18,Paramètres!$C$18,IF(M25<Paramètres!$B$19,Paramètres!$C$19,IF(M25<Paramètres!$B$20,Paramètres!$C$20,IF(M25<Paramètres!$B$21,Paramètres!$C$21,Paramètres!$C$22))))))))),M25),"") -> De 50 à 54 ans | R25: =+IF(N25="Mr",1,2) -> 1 | S25: =K25*(DATEDIF(F25,TODAY(),"m")/12) -> 28.083333 | T25: =IF(K25=1,IF(Paramètres!$E$25,IF(S25<Paramètres!$B$29,Paramètres!$C$29,IF(S25<Paramètres!$B$30,Paramètres!$C$30,IF(S25<Paramètres!$B$31,Paramètres!$C$31,IF(S25<Paramètres!$B$32,Paramètres!$C$32,IF(S25<Paramètres!$B$33,Paramètres!$C$33,IF(S25<Paramètres!$B$34,Paramètres!$C$34,IF(S25<Paramètres!$B$35,Paramètres!$C$35,IF(S25<Paramètres!$B$36,Paramètres!$C$36,IF(S25<Paramètres!$B$37,Paramètres!$C$37,Paramètres!$C$38))))))))),[3]Données!P472),"") -> De 25 à 29 ans
A26: 458 | B26: AZIZI | C26: MUSTAPHA | D26: Nador | E26: Maitrise | F26: 35947 | G26: "2MAI02 | H26: 26186 | I26: =H26+(365.25*60) -> 48101 | K26: 1 | M26: =K26*(DATEDIF(H26,TODAY(),"m")/12) -> 54.75 | N26: Mr | O26: CDI | P26: NADOR | Q26: =IF(K26=1,IF(Paramètres!$E$9,IF(M26<Paramètres!$B$13,Paramètres!$C$13,IF(M26<Paramètres!$B$14,Paramètres!$C$14,IF(M26<Paramètres!$B$15,Paramètres!$C$15,IF(M26<Paramètres!$B$16,Paramètres!$C$16,IF(M26<Paramètres!$B$17,Paramètres!$C$17,IF(M26<Paramètres!$B$18,Paramètres!$C$18,IF(M26<Paramètres!$B$19,Paramètres!$C$19,IF(M26<Paramètres!$B$20,Paramètres!$C$20,IF(M26<Paramètres!$B$21,Paramètres!$C$21,Paramètres!$C$22))))))))),M26),"") -> De 50 à 54 ans | R26: =+IF(N26="Mr",1,2) -> 1 | S26: =K26*(DATEDIF(F26,TODAY(),"m")/12) -> 28.083333 | T26: =IF(K26=1,IF(Paramètres!$E$25,IF(S26<Paramètres!$B$29,Paramètres!$C$29,IF(S26<Paramètres!$B$30,Paramètres!$C$30,IF(S26<Paramètres!$B$31,Paramètres!$C$31,IF(S26<Paramètres!$B$32,Paramètres!$C$32,IF(S26<Paramètres!$B$33,Paramètres!$C$33,IF(S26<Paramètres!$B$34,Paramètres!$C$34,IF(S26<Paramètres!$B$35,Paramètres!$C$35,IF(S26<Paramètres!$B$36,Paramètres!$C$36,IF(S26<Paramètres!$B$37,Paramètres!$C$37,Paramètres!$C$38))))))))),[3]Données!P473),"") -> De 25 à 29 ans
A27: 459 | B27: BEN OTMAN | C27: JAMAL | D27: Nador | E27: Maitrise | F27: 35947 | G27: "2SGX01 | H27: 25913 | I27: =H27+(365.25*60) -> 47828 | K27: 1 | M27: =K27*(DATEDIF(H27,TODAY(),"m")/12) -> 55.5 | N27: Mr | O27: CDI | P27: NADOR | Q27: =IF(K27=1,IF(Paramètres!$E$9,IF(M27<Paramètres!$B$13,Paramètres!$C$13,IF(M27<Paramètres!$B$14,Paramètres!$C$14,IF(M27<Paramètres!$B$15,Paramètres!$C$15,IF(M27<Paramètres!$B$16,Paramètres!$C$16,IF(M27<Paramètres!$B$17,Paramètres!$C$17,IF(M27<Paramètres!$B$18,Paramètres!$C$18,IF(M27<Paramètres!$B$19,Paramètres!$C$19,IF(M27<Paramètres!$B$20,Paramètres!$C$20,IF(M27<Paramètres!$B$21,Paramètres!$C$21,Paramètres!$C$22))))))))),M27),"") -> De 55 à 59 ans | R27: =+IF(N27="Mr",1,2) -> 1 | S27: =K27*(DATEDIF(F27,TODAY(),"m")/12) -> 28.083333 | T27: =IF(K27=1,IF(Paramètres!$E$25,IF(S27<Paramètres!$B$29,Paramètres!$C$29,IF(S27<Paramètres!$B$30,Paramètres!$C$30,IF(S27<Paramètres!$B$31,Paramètres!$C$31,IF(S27<Paramètres!$B$32,Paramètres!$C$32,IF(S27<Paramètres!$B$33,Paramètres!$C$33,IF(S27<Paramètres!$B$34,Paramètres!$C$34,IF(S27<Paramètres!$B$35,Paramètres!$C$35,IF(S27<Paramètres!$B$36,Paramètres!$C$36,IF(S27<Paramètres!$B$37,Paramètres!$C$37,Paramètres!$C$38))))))))),[3]Données!P474),"") -> De 25 à 29 ans
A28: 462 | B28: LAAZIBI | C28: MOHAMED | D28: Nador | E28: Maitrise | F28: 35947 | G28: "2SGX01 | H28: 26404 | I28: =H28+(365.25*60) -> 48319 | K28: 1 | M28: =K28*(DATEDIF(H28,TODAY(),"m")/12) -> 54.166667 | N28: Mr | O28: CDI | P28: NADOR | Q28: =IF(K28=1,IF(Paramètres!$E$9,IF(M28<Paramètres!$B$13,Paramètres!$C$13,IF(M28<Paramètres!$B$14,Paramètres!$C$14,IF(M28<Paramètres!$B$15,Paramètres!$C$15,IF(M28<Paramètres!$B$16,Paramètres!$C$16,IF(M28<Paramètres!$B$17,Paramètres!$C$17,IF(M28<Paramètres!$B$18,Paramètres!$C$18,IF(M28<Paramètres!$B$19,Paramètres!$C$19,IF(M28<Paramètres!$B$20,Paramètres!$C$20,IF(M28<Paramètres!$B$21,Paramètres!$C$21,Paramètres!$C$22))))))))),M28),"") -> De 50 à 54 ans | R28: =+IF(N28="Mr",1,2) -> 1 | S28: =K28*(DATEDIF(F28,TODAY(),"m")/12) -> 28.083333 | T28: =IF(K28=1,IF(Paramètres!$E$25,IF(S28<Paramètres!$B$29,Paramètres!$C$29,IF(S28<Paramètres!$B$30,Paramètres!$C$30,IF(S28<Paramètres!$B$31,Paramètres!$C$31,IF(S28<Paramètres!$B$32,Paramètres!$C$32,IF(S28<Paramètres!$B$33,Paramètres!$C$33,IF(S28<Paramètres!$B$34,Paramètres!$C$34,IF(S28<Paramètres!$B$35,Paramètres!$C$35,IF(S28<Paramètres!$B$36,Paramètres!$C$36,IF(S28<Paramètres!$B$37,Paramètres!$C$37,Paramètres!$C$38))))))))),[3]Données!P475),"") -> De 25 à 29 ans
A29: 464 | B29: MAZOUJI | C29: MIMOUN | D29: Nador | E29: Employé | F29: 35947 | G29: "2MAI06 | H29: 25361 | I29: =H29+(365.25*60) -> 47276 | K29: 1 | M29: =K29*(DATEDIF(H29,TODAY(),"m")/12) -> 57.083333 | N29: Mr | O29: CDI | P29: NADOR | Q29: =IF(K29=1,IF(Paramètres!$E$9,IF(M29<Paramètres!$B$13,Paramètres!$C$13,IF(M29<Paramètres!$B$14,Paramètres!$C$14,IF(M29<Paramètres!$B$15,Paramètres!$C$15,IF(M29<Paramètres!$B$16,Paramètres!$C$16,IF(M29<Paramètres!$B$17,Paramètres!$C$17,IF(M29<Paramètres!$B$18,Paramètres!$C$18,IF(M29<Paramètres!$B$19,Paramètres!$C$19,IF(M29<Paramètres!$B$20,Paramètres!$C$20,IF(M29<Paramètres!$B$21,Paramètres!$C$21,Paramètres!$C$22))))))))),M29),"") -> De 55 à 59 ans | R29: =+IF(N29="Mr",1,2) -> 1 | S29: =K29*(DATEDIF(F29,TODAY(),"m")/12) -> 28.083333 | T29: =IF(K29=1,IF(Paramètres!$E$25,IF(S29<Paramètres!$B$29,Paramètres!$C$29,IF(S29<Paramètres!$B$30,Paramètres!$C$30,IF(S29<Paramètres!$B$31,Paramètres!$C$31,IF(S29<Paramètres!$B$32,Paramètres!$C$32,IF(S29<Paramètres!$B$33,Paramètres!$C$33,IF(S29<Paramètres!$B$34,Paramètres!$C$34,IF(S29<Paramètres!$B$35,Paramètres!$C$35,IF(S29<Paramètres!$B$36,Paramètres!$C$36,IF(S29<Paramètres!$B$37,Paramètres!$C$37,Paramètres!$C$38))))))))),[3]Données!P476),"") -> De 25 à 29 ans
... A46: 490 | B46: JIYAR | C46: EL MILOUD | D46: Nador | E46: Employé | F46: 35996 | G46: "2MAI03 | H46: 27529 | I46: =H46+(365.25*60) -> 49444 | K46: 1 | M46: =K46*(DATEDIF(H46,TODAY(),"m")/12) -> 51.083333 | N46: Mr | O46: CDI | P46: NADOR | Q46: =IF(K46=1,IF(Paramètres!$E$9,IF(M46<Paramètres!$B$13,Paramètres!$C$13,IF(M46<Paramètres!$B$14,Paramètres!$C$14,IF(M46<Paramètres!$B$15,Paramètres!$C$15,IF(M46<Paramètres!$B$16,Paramètres!$C$16,IF(M46<Paramètres!$B$17,Paramètres!$C$17,IF(M46<Paramètres!$B$18,Paramètres!$C$18,IF(M46<Paramètres!$B$19,Paramètres!$C$19,IF(M46<Paramètres!$B$20,Paramètres!$C$20,IF(M46<Paramètres!$B$21,Paramètres!$C$21,Paramètres!$C$22))))))))),M46),"") -> De 50 à 54 ans | R46: =+IF(N46="Mr",1,2) -> 1 | S46: =K46*(DATEDIF(F46,TODAY(),"m")/12) -> 27.916667 | T46: =IF(K46=1,IF(Paramètres!$E$25,IF(S46<Paramètres!$B$29,Paramètres!$C$29,IF(S46<Paramètres!$B$30,Paramètres!$C$30,IF(S46<Paramètres!$B$31,Paramètres!$C$31,IF(S46<Paramètres!$B$32,Paramètres!$C$32,IF(S46<Paramètres!$B$33,Paramètres!$C$33,IF(S46<Paramètres!$B$34,Paramètres!$C$34,IF(S46<Paramètres!$B$35,Paramètres!$C$35,IF(S46<Paramètres!$B$36,Paramètres!$C$36,IF(S46<Paramètres!$B$37,Paramètres!$C$37,Paramètres!$C$38))))))))),[3]Données!P493),"") -> De 25 à 29 ans
A47: 491 | B47: KOUBAA | C47: HASSAN | D47: Nador | E47: Employé | F47: 35996 | G47: "2PRO05 | H47: 23903 | I47: =H47+(365.25*60) -> 45818 | J47: 45818 | K47: 0 | L47: Retraite | M47: =K47*(DATEDIF(H47,TODAY(),"m")/12) -> 0 | N47: Mr | P47: NADOR | Q47: =IF(K47=1,IF(Paramètres!$E$9,IF(M47<Paramètres!$B$13,Paramètres!$C$13,IF(M47<Paramètres!$B$14,Paramètres!$C$14,IF(M47<Paramètres!$B$15,Paramètres!$C$15,IF(M47<Paramètres!$B$16,Paramètres!$C$16,IF(M47<Paramètres!$B$17,Paramètres!$C$17,IF(M47<Paramètres!$B$18,Paramètres!$C$18,IF(M47<Paramètres!$B$19,Paramètres!$C$19,IF(M47<Paramètres!$B$20,Paramètres!$C$20,IF(M47<Paramètres!$B$21,Paramètres!$C$21,Paramètres!$C$22))))))))),M47),"") | R47: =+IF(N47="Mr",1,2) -> 1 | S47: =K47*(DATEDIF(F47,TODAY(),"m")/12) -> 0 | T47: =IF(K47=1,IF(Paramètres!$E$25,IF(S47<Paramètres!$B$29,Paramètres!$C$29,IF(S47<Paramètres!$B$30,Paramètres!$C$30,IF(S47<Paramètres!$B$31,Paramètres!$C$31,IF(S47<Paramètres!$B$32,Paramètres!$C$32,IF(S47<Paramètres!$B$33,Paramètres!$C$33,IF(S47<Paramètres!$B$34,Paramètres!$C$34,IF(S47<Paramètres!$B$35,Paramètres!$C$35,IF(S47<Paramètres!$B$36,Paramètres!$C$36,IF(S47<Paramètres!$B$37,Paramètres!$C$37,Paramètres!$C$38))))))))),[3]Données!P604),"")
A48: 492 | B48: LAGHRABLI | C48: BOUCHTA | D48: Nador | E48: Maitrise | F48: 35996 | G48: "2MAI03 | H48: 27837 | I48: =H48+(365.25*60) -> 49752 | K48: 1 | M48: =K48*(DATEDIF(H48,TODAY(),"m")/12) -> 50.25 | N48: Mr | O48: CDI | P48: NADOR | Q48: =IF(K48=1,IF(Paramètres!$E$9,IF(M48<Paramètres!$B$13,Paramètres!$C$13,IF(M48<Paramètres!$B$14,Paramètres!$C$14,IF(M48<Paramètres!$B$15,Paramètres!$C$15,IF(M48<Paramètres!$B$16,Paramètres!$C$16,IF(M48<Paramètres!$B$17,Paramètres!$C$17,IF(M48<Paramètres!$B$18,Paramètres!$C$18,IF(M48<Paramètres!$B$19,Paramètres!$C$19,IF(M48<Paramètres!$B$20,Paramètres!$C$20,IF(M48<Paramètres!$B$21,Paramètres!$C$21,Paramètres!$C$22))))))))),M48),"") -> De 50 à 54 ans | R48: =+IF(N48="Mr",1,2) -> 1 | S48: =K48*(DATEDIF(F48,TODAY(),"m")/12) -> 27.916667 | T48: =IF(K48=1,IF(Paramètres!$E$25,IF(S48<Paramètres!$B$29,Paramètres!$C$29,IF(S48<Paramètres!$B$30,Paramètres!$C$30,IF(S48<Paramètres!$B$31,Paramètres!$C$31,IF(S48<Paramètres!$B$32,Paramètres!$C$32,IF(S48<Paramètres!$B$33,Paramètres!$C$33,IF(S48<Paramètres!$B$34,Paramètres!$C$34,IF(S48<Paramètres!$B$35,Paramètres!$C$35,IF(S48<Paramètres!$B$36,Paramètres!$C$36,IF(S48<Paramètres!$B$37,Paramètres!$C$37,Paramètres!$C$38))))))))),[3]Données!P494),"") -> De 25 à 29 ans
A49: 493 | B49: LAZREG | C49: ABDESLAM | D49: Nador | E49: Maitrise | F49: 35996 | G49: "2MAI04 | H49: 26048 | I49: =H49+(365.25*60) -> 47963 | K49: 1 | M49: =K49*(DATEDIF(H49,TODAY(),"m")/12) -> 55.166667 | N49: Mr | O49: CDI | P49: NADOR | Q49: =IF(K49=1,IF(Paramètres!$E$9,IF(M49<Paramètres!$B$13,Paramètres!$C$13,IF(M49<Paramètres!$B$14,Paramètres!$C$14,IF(M49<Paramètres!$B$15,Paramètres!$C$15,IF(M49<Paramètres!$B$16,Paramètres!$C$16,IF(M49<Paramètres!$B$17,Paramètres!$C$17,IF(M49<Paramètres!$B$18,Paramètres!$C$18,IF(M49<Paramètres!$B$19,Paramètres!$C$19,IF(M49<Paramètres!$B$20,Paramètres!$C$20,IF(M49<Paramètres!$B$21,Paramètres!$C$21,Paramètres!$C$22))))))))),M49),"") -> De 55 à 59 ans | R49: =+IF(N49="Mr",1,2) -> 1 | S49: =K49*(DATEDIF(F49,TODAY(),"m")/12) -> 27.916667 | T49: =IF(K49=1,IF(Paramètres!$E$25,IF(S49<Paramètres!$B$29,Paramètres!$C$29,IF(S49<Paramètres!$B$30,Paramètres!$C$30,IF(S49<Paramètres!$B$31,Paramètres!$C$31,IF(S49<Paramètres!$B$32,Paramètres!$C$32,IF(S49<Paramètres!$B$33,Paramètres!$C$33,IF(S49<Paramètres!$B$34,Paramètres!$C$34,IF(S49<Paramètres!$B$35,Paramètres!$C$35,IF(S49<Paramètres!$B$36,Paramètres!$C$36,IF(S49<Paramètres!$B$37,Paramètres!$C$37,Paramètres!$C$38))))))))),[3]Données!P495),"") -> De 25 à 29 ans
A50: 494 | B50: MACHROUT | C50: RACHID | D50: Nador | E50: Employé | F50: 35996 | G50: "2PRO06 | H50: 26872 | I50: =H50+(365.25*60) -> 48787 | K50: 1 | M50: =K50*(DATEDIF(H50,TODAY(),"m")/12) -> 52.916667 | N50: Mr | O50: CDI | P50: NADOR | Q50: =IF(K50=1,IF(Paramètres!$E$9,IF(M50<Paramètres!$B$13,Paramètres!$C$13,IF(M50<Paramètres!$B$14,Paramètres!$C$14,IF(M50<Paramètres!$B$15,Paramètres!$C$15,IF(M50<Paramètres!$B$16,Paramètres!$C$16,IF(M50<Paramètres!$B$17,Paramètres!$C$17,IF(M50<Paramètres!$B$18,Paramètres!$C$18,IF(M50<Paramètres!$B$19,Paramètres!$C$19,IF(M50<Paramètres!$B$20,Paramètres!$C$20,IF(M50<Paramètres!$B$21,Paramètres!$C$21,Paramètres!$C$22))))))))),M50),"") -> De 50 à 54 ans | R50: =+IF(N50="Mr",1,2) -> 1 | S50: =K50*(DATEDIF(F50,TODAY(),"m")/12) -> 27.916667 | T50: =IF(K50=1,IF(Paramètres!$E$25,IF(S50<Paramètres!$B$29,Paramètres!$C$29,IF(S50<Paramètres!$B$30,Paramètres!$C$30,IF(S50<Paramètres!$B$31,Paramètres!$C$31,IF(S50<Paramètres!$B$32,Paramètres!$C$32,IF(S50<Paramètres!$B$33,Paramètres!$C$33,IF(S50<Paramètres!$B$34,Paramètres!$C$34,IF(S50<Paramètres!$B$35,Paramètres!$C$35,IF(S50<Paramètres!$B$36,Paramètres!$C$36,IF(S50<Paramètres!$B$37,Paramètres!$C$37,Paramètres!$C$38))))))))),[3]Données!P496),"") -> De 25 à 29 ans
A51: 495 | B51: OUHADDOU | C51: MOHAMED | D51: Nador | E51: Maitrise | F51: 35996 | G51: "2MAI03 | H51: 27305 | I51: =H51+(365.25*60) -> 49220 | K51: 1 | M51: =K51*(DATEDIF(H51,TODAY(),"m")/12) -> 51.75 | N51: Mr | O51: CDI | P51: NADOR | Q51: =IF(K51=1,IF(Paramètres!$E$9,IF(M51<Paramètres!$B$13,Paramètres!$C$13,IF(M51<Paramètres!$B$14,Paramètres!$C$14,IF(M51<Paramètres!$B$15,Paramètres!$C$15,IF(M51<Paramètres!$B$16,Paramètres!$C$16,IF(M51<Paramètres!$B$17,Paramètres!$C$17,IF(M51<Paramètres!$B$18,Paramètres!$C$18,IF(M51<Paramètres!$B$19,Paramètres!$C$19,IF(M51<Paramètres!$B$20,Paramètres!$C$20,IF(M51<Paramètres!$B$21,Paramètres!$C$21,Paramètres!$C$22))))))))),M51),"") -> De 50 à 54 ans | R51: =+IF(N51="Mr",1,2) -> 1 | S51: =K51*(DATEDIF(F51,TODAY(),"m")/12) -> 27.916667 | T51: =IF(K51=1,IF(Paramètres!$E$25,IF(S51<Paramètres!$B$29,Paramètres!$C$29,IF(S51<Paramètres!$B$30,Paramètres!$C$30,IF(S51<Paramètres!$B$31,Paramètres!$C$31,IF(S51<Paramètres!$B$32,Paramètres!$C$32,IF(S51<Paramètres!$B$33,Paramètres!$C$33,IF(S51<Paramètres!$B$34,Paramètres!$C$34,IF(S51<Paramètres!$B$35,Paramètres!$C$35,IF(S51<Paramètres!$B$36,Paramètres!$C$36,IF(S51<Paramètres!$B$37,Paramètres!$C$37,Paramètres!$C$38))))))))),[3]Données!P497),"") -> De 25 à 29 ans
A52: 496 | B52: RADI | C52: ABDELKRIM | D52: Nador | E52: Maitrise | F52: 35996 | G52: "2MAI02 | H52: 26177 | I52: =H52+(365.25*60) -> 48092 | K52: 1 | M52: =K52*(DATEDIF(H52,TODAY(),"m")/12) -> 54.833333 | N52: Mr | O52: CDI | P52: NADOR | Q52: =IF(K52=1,IF(Paramètres!$E$9,IF(M52<Paramètres!$B$13,Paramètres!$C$13,IF(M52<Paramètres!$B$14,Paramètres!$C$14,IF(M52<Paramètres!$B$15,Paramètres!$C$15,IF(M52<Paramètres!$B$16,Paramètres!$C$16,IF(M52<Paramètres!$B$17,Paramètres!$C$17,IF(M52<Paramètres!$B$18,Paramètres!$C$18,IF(M52<Paramètres!$B$19,Paramètres!$C$19,IF(M52<Paramètres!$B$20,Paramètres!$C$20,IF(M52<Paramètres!$B$21,Paramètres!$C$21,Paramètres!$C$22))))))))),M52),"") -> De 50 à 54 ans | R52: =+IF(N52="Mr",1,2) -> 1 | S52: =K52*(DATEDIF(F52,TODAY(),"m")/12) -> 27.916667 | T52: =IF(K52=1,IF(Paramètres!$E$25,IF(S52<Paramètres!$B$29,Paramètres!$C$29,IF(S52<Paramètres!$B$30,Paramètres!$C$30,IF(S52<Paramètres!$B$31,Paramètres!$C$31,IF(S52<Paramètres!$B$32,Paramètres!$C$32,IF(S52<Paramètres!$B$33,Paramètres!$C$33,IF(S52<Paramètres!$B$34,Paramètres!$C$34,IF(S52<Paramètres!$B$35,Paramètres!$C$35,IF(S52<Paramètres!$B$36,Paramètres!$C$36,IF(S52<Paramètres!$B$37,Paramètres!$C$37,Paramètres!$C$38))))))))),[3]Données!P498),"") -> De 25 à 29 ans
A53: 497 | B53: ROUMANI | C53: BRAHIM | D53: Nador | E53: Employé | F53: 35996 | G53: "2PRO02 | H53: 26361 | I53: =H53+(365.25*60) -> 48276 | K53: 1 | M53: =K53*(DATEDIF(H53,TODAY(),"m")/12) -> 54.333333 | N53: Mr | O53: CDI | P53: NADOR | Q53: =IF(K53=1,IF(Paramètres!$E$9,IF(M53<Paramètres!$B$13,Paramètres!$C$13,IF(M53<Paramètres!$B$14,Paramètres!$C$14,IF(M53<Paramètres!$B$15,Paramètres!$C$15,IF(M53<Paramètres!$B$16,Paramètres!$C$16,IF(M53<Paramètres!$B$17,Paramètres!$C$17,IF(M53<Paramètres!$B$18,Paramètres!$C$18,IF(M53<Paramètres!$B$19,Paramètres!$C$19,IF(M53<Paramètres!$B$20,Paramètres!$C$20,IF(M53<Paramètres!$B$21,Paramètres!$C$21,Paramètres!$C$22))))))))),M53),"") -> De 50 à 54 ans | R53: =+IF(N53="Mr",1,2) -> 1 | S53: =K53*(DATEDIF(F53,TODAY(),"m")/12) -> 27.916667 | T53: =IF(K53=1,IF(Paramètres!$E$25,IF(S53<Paramètres!$B$29,Paramètres!$C$29,IF(S53<Paramètres!$B$30,Paramètres!$C$30,IF(S53<Paramètres!$B$31,Paramètres!$C$31,IF(S53<Paramètres!$B$32,Paramètres!$C$32,IF(S53<Paramètres!$B$33,Paramètres!$C$33,IF(S53<Paramètres!$B$34,Paramètres!$C$34,IF(S53<Paramètres!$B$35,Paramètres!$C$35,IF(S53<Paramètres!$B$36,Paramètres!$C$36,IF(S53<Paramètres!$B$37,Paramètres!$C$37,Paramètres!$C$38))))))))),[3]Données!P499),"") -> De 25 à 29 ans
A54: 498 | B54: TALEB | C54: MOHAMMED | D54: Nador | E54: Employé | F54: 35996 | G54: "2MAI09 | H54: 25749 | I54: =H54+(365.25*60) -> 47664 | K54: 1 | M54: =K54*(DATEDIF(H54,TODAY(),"m")/12) -> 56 | N54: Mr | O54: CDI | P54: NADOR | Q54: =IF(K54=1,IF(Paramètres!$E$9,IF(M54<Paramètres!$B$13,Paramètres!$C$13,IF(M54<Paramètres!$B$14,Paramètres!$C$14,IF(M54<Paramètres!$B$15,Paramètres!$C$15,IF(M54<Paramètres!$B$16,Paramètres!$C$16,IF(M54<Paramètres!$B$17,Paramètres!$C$17,IF(M54<Paramètres!$B$18,Paramètres!$C$18,IF(M54<Paramètres!$B$19,Paramètres!$C$19,IF(M54<Paramètres!$B$20,Paramètres!$C$20,IF(M54<Paramètres!$B$21,Paramètres!$C$21,Paramètres!$C$22))))))))),M54),"") -> De 55 à 59 ans | R54: =+IF(N54="Mr",1,2) -> 1 | S54: =K54*(DATEDIF(F54,TODAY(),"m")/12) -> 27.916667 | T54: =IF(K54=1,IF(Paramètres!$E$25,IF(S54<Paramètres!$B$29,Paramètres!$C$29,IF(S54<Paramètres!$B$30,Paramètres!$C$30,IF(S54<Paramètres!$B$31,Paramètres!$C$31,IF(S54<Paramètres!$B$32,Paramètres!$C$32,IF(S54<Paramètres!$B$33,Paramètres!$C$33,IF(S54<Paramètres!$B$34,Paramètres!$C$34,IF(S54<Paramètres!$B$35,Paramètres!$C$35,IF(S54<Paramètres!$B$36,Paramètres!$C$36,IF(S54<Paramètres!$B$37,Paramètres!$C$37,Paramètres!$C$38))))))))),[3]Données!P500),"") -> De 25 à 29 ans
A55: 499 | B55: CHOURI | C55: ALI | D55: Nador | E55: Employé | F55: 35997 | G55: "2MAI03 | H55: 26602 | I55: =H55+(365.25*60) -> 48517 | J55: 45870 | K55: 0 | L55: Démission | M55: =K55*(DATEDIF(H55,TODAY(),"m")/12) -> 0 | N55: Mr | P55: NADOR | Q55: =IF(K55=1,IF(Paramètres!$E$9,IF(M55<Paramètres!$B$13,Paramètres!$C$13,IF(M55<Paramètres!$B$14,Paramètres!$C$14,IF(M55<Paramètres!$B$15,Paramètres!$C$15,IF(M55<Paramètres!$B$16,Paramètres!$C$16,IF(M55<Paramètres!$B$17,Paramètres!$C$17,IF(M55<Paramètres!$B$18,Paramètres!$C$18,IF(M55<Paramètres!$B$19,Paramètres!$C$19,IF(M55<Paramètres!$B$20,Paramètres!$C$20,IF(M55<Paramètres!$B$21,Paramètres!$C$21,Paramètres!$C$22))))))))),M55),"") | R55: =+IF(N55="Mr",1,2) -> 1 | S55: =K55*(DATEDIF(F55,TODAY(),"m")/12) -> 0 | T55: =IF(K55=1,IF(Paramètres!$E$25,IF(S55<Paramètres!$B$29,Paramètres!$C$29,IF(S55<Paramètres!$B$30,Paramètres!$C$30,IF(S55<Paramètres!$B$31,Paramètres!$C$31,IF(S55<Paramètres!$B$32,Paramètres!$C$32,IF(S55<Paramètres!$B$33,Paramètres!$C$33,IF(S55<Paramètres!$B$34,Paramètres!$C$34,IF(S55<Paramètres!$B$35,Paramètres!$C$35,IF(S55<Paramètres!$B$36,Paramètres!$C$36,IF(S55<Paramètres!$B$37,Paramètres!$C$37,Paramètres!$C$38))))))))),[3]Données!P605),"")
A56: 504 | B56: EL BOUJADAYNI | C56: AHMED AZDIN | D56: Nador | E56: Employé | F56: 36039 | G56: "2PRO06 | H56: 24416 | I56: =H56+(365.25*60) -> 46331 | K56: 1 | M56: =K56*(DATEDIF(H56,TODAY(),"m")/12) -> 59.666667 | N56: Mr | O56: CDI | P56: NADOR | Q56: =IF(K56=1,IF(Paramètres!$E$9,IF(M56<Paramètres!$B$13,Paramètres!$C$13,IF(M56<Paramètres!$B$14,Paramètres!$C$14,IF(M56<Paramètres!$B$15,Paramètres!$C$15,IF(M56<Paramètres!$B$16,Paramètres!$C$16,IF(M56<Paramètres!$B$17,Paramètres!$C$17,IF(M56<Paramètres!$B$18,Paramètres!$C$18,IF(M56<Paramètres!$B$19,Paramètres!$C$19,IF(M56<Paramètres!$B$20,Paramètres!$C$20,IF(M56<Paramètres!$B$21,Paramètres!$C$21,Paramètres!$C$22))))))))),M56),"") -> De 55 à 59 ans | R56: =+IF(N56="Mr",1,2) -> 1 | S56: =K56*(DATEDIF(F56,TODAY(),"m")/12) -> 27.833333 | T56: =IF(K56=1,IF(Paramètres!$E$25,IF(S56<Paramètres!$B$29,Paramètres!$C$29,IF(S56<Paramètres!$B$30,Paramètres!$C$30,IF(S56<Paramètres!$B$31,Paramètres!$C$31,IF(S56<Paramètres!$B$32,Paramètres!$C$32,IF(S56<Paramètres!$B$33,Paramètres!$C$33,IF(S56<Paramètres!$B$34,Paramètres!$C$34,IF(S56<Paramètres!$B$35,Paramètres!$C$35,IF(S56<Paramètres!$B$36,Paramètres!$C$36,IF(S56<Paramètres!$B$37,Paramètres!$C$37,Paramètres!$C$38))))))))),[3]Données!P501),"") -> De 25 à 29 ans
...

Sheet Feuil3
A1: Matricule | B1: Nom | C1: Prenom | D1: Lieu de travail | E1: Base | F1: PRIME_REPRESENT | G1: Indemnité transport | H1: Indemnité poste | I1: Prime logement | J1: P logement n logé | K1: P logement logé | L1: P logement famille | M1: Indemnité encadrement | N1: Indemnité panier | O1: Indemnité chaleur | P1: Indemnité salissure | Q1: Indemnité poste douche | R1: Indemnité contre maitre | S1: Indemnité velomoteur | T1: Indemnité dimanche | U1: Prime caisse | V1: Forfait HS | W1: Indemnité compensatrice | X1: Indémnité chef de poste | Y1: Collège | Z1: Echelle | AA1: DEB_CONTRAT | AB1: FIN_CONTRAT | AC1: DT_NAISSANCE | AD1: Famille | AE1: CIVILITE | AF1: Taux Prime ancienneté | AG1: C cout
A2: 1537 | B2: OUASS | C2: ANAS | D2: Nador | Y2: Employé | Z2: B | AA2: 44986 | AC2: 35885 | AD2: M | AE2: Mr | AF2: 0 | AG2: 2FIB01
A3: 1513 | B3: BOULMANE | C3: YOUSSEF | D3: Nador | Y3: Employé | Z3: B | AA3: 44928 | AC3: 37098 | AD3: C | AE3: Mr | AF3: 5 | AG3: 2FIB01
A4: 1516 | B4: BOUHASSOUN | C4: MOURAD | D4: Nador | Y4: Employé | Z4: B | AA4: 44928 | AC4: 32738 | AD4: M | AE4: Mr | AF4: 5 | AG4: 2FIB01
A5: 1628 | B5: ECH-CHAYKH | C5: KARIM | D5: Nador | Y5: Employé | Z5: B | AA5: 45383 | AC5: 37320 | AD5: C | AE5: Mr | AF5: 0 | AG5: 2FIB01
A6: 456 | B6: ARRAISS | C6: ABDESLAM | D6: Nador | Y6: Maitrise | Z6: D | AA6: 35947 | AC6: 26344 | AD6: M | AE6: Mr | AF6: 25 | AG6: 2FIB01
A7: 1525 | B7: KHLAIF | C7: ABDERRAHMANE | D7: Nador | Y7: Employé | Z7: B | AA7: 44972 | AC7: 36825 | AD7: M | AE7: Mr | AF7: 0 | AG7: 2FIB01
A8: 1536 | B8: KABBOUCH | C8: ABDERRAHIM | D8: Nador | Y8: Employé | Z8: B | AA8: 44986 | AC8: 34396 | AD8: M | AE8: Mr | AF8: 0 | AG8: 2FIB01
A9: 1559 | B9: BOUHRICHE | C9: Ayoub | D9: Nador | Y9: Employé | Z9: B | AA9: 45108 | AC9: 33792 | AD9: C | AE9: Mr | AF9: 0 | AG9: 2FIB01
A10: 309 | B10: AMDARI | C10: MUSTAPHA | D10: Nador | Y10: Maitrise | Z10: 3 | AA10: 32539 | AC10: 25653 | AD10: M | AE10: Mr | AF10: 25 | AG10: 2FIB01
A11: 512 | B11: ER RAJI | C11: MOHAMED | D11: Nador | Y11: Maitrise | Z11: D | AA11: 36472 | AC11: 29036 | AD11: M | AE11: Mr | AF11: 25 | AG11: 2FIB01
A12: 1538 | B12: TABARRANT | C12: ABDELHASSIB | D12: Nador | Y12: Employé | Z12: B | AA12: 44998 | AC12: 35942 | AD12: M | AE12: Mr | AF12: 0 | AG12: 2FIB01
A13: 1594 | B13: OUTAASSOUTE | C13: TAWFIQ | D13: Nador | Y13: Employé | Z13: B | AA13: 45293 | AC13: 36960 | AD13: C | AE13: Mr | AF13: 0 | AG13: 2FIB01
A14: 1629 | B14: DAOUDI | C14: ABDESSAMAD | D14: Nador | Y14: Employé | Z14: B | AA14: 45383 | AC14: 36510 | AD14: C | AE14: Mr | AF14: 0 | AG14: 2FIB01
A15: 1630 | B15: DRAOUI | C15: ABDELOUAHID | D15: Nador | Y15: Employé | Z15: B | AA15: 45383 | AC15: 34780 | AD15: C | AE15: Mr | AF15: 0 | AG15: 2FIB01
A16: 344 | B16: EL AMMARI | C16: MOHAMED | D16: Nador | Y16: Maitrise | Z16: 4 | AA16: 33085 | AB16: 45953 | AC16: 24038 | AD16: M | AE16: Mr | AF16: 25 | AG16: 2FIB01
A17: 1280 | B17: HACHMI | C17: MUSTAPHA | D17: Nador | Y17: Maitrise | Z17: F | AA17: 41981 | AC17: 26299 | AD17: M | AE17: Mr | AF17: 10 | AG17: 2TVN01
A18: 393 | B18: TALAA | C18: M'HAMMED | D18: Nador | Y18: Maitrise | Z18: 4 | AA18: 34554 | AC18: 25165 | AD18: M | AE18: Mr | AF18: 25 | AG18: 2NAD01
A19: 372 | B19: ABDAIM | C19: LAHOUCINE | D19: Nador | Y19: Employé | Z19: 10 | AA19: 33948 | AC19: 27210 | AD19: M | AE19: Mr | AF19: 25 | AG19: 2NAD01
A20: 367 | B20: AKAAOUCH | C20: ALI | D20: Nador | Y20: Maitrise | Z20: 5 | AA20: 33637 | AC20: 25494 | AD20: M | AE20: Mr | AF20: 25 | AG20: 2NAD01
A21: 354 | B21: EL IDRISSI | C21: NOUREDDINE | D21: Nador | Y21: Employé | Z21: 8 | AA21: 33233 | AB21: 45782 | AC21: 23867 | AD21: C | AE21: Mr | AF21: 25 | AG21: 2NAD01
A22: 347 | B22: AOUANE | C22: ABDENBI | D22: Nador | Y22: Maitrise | Z22: 5 | AA22: 33148 | AC22: 24867 | AD22: M | AE22: Mr | AF22: 25 | AG22: 2NAD01
A23: 332 | B23: RHANJATI | C23: MOHAMED | D23: Nador | Y23: Employé | Z23: 10 | AA23: 32898 | AC23: 26218 | AD23: M | AE23: Mr | AF23: 25 | AG23: 2NAD01
A24: 1514 | B24: EL-MORSLI | C24: MOHAMED | D24: Nador | Y24: Employé | Z24: B | AA24: 44914 | AC24: 35412 | AD24: C | AE24: Mr | AF24: 5 | AG24: 2NAD01
A25: 597 | B25: CHAOUCH | C25: RADOAN | D25: Nador | Y25: Maitrise | Z25: E | AA25: 37459 | AC25: 26873 | AD25: V | AE25: Mr | AF25: 20 | AG25: 2NAD01
A26: 1081 | B26: ELHARROUTI | C26: TIJANI | D26: Nador | Y26: Maitrise | Z26: E | AA26: 39853 | AC26: 31499 | AD26: M | AE26: Mr | AF26: 15 | AG26: 2NAD01
A27: 1082 | B27: EL BARRAGHI | C27: RACHID | D27: Nador | Y27: Maitrise | Z27: D | AA27: 39860 | AC27: 31635 | AD27: M | AE27: Mr | AF27: 15 | AG27: 2NAD01
A28: 1532 | B28: ALLOU | C28: DRISS | D28: Nador | Y28: Employé | Z28: C | AA28: 44986 | AC28: 31779 | AD28: M | AE28: Mr | AF28: 0 | AG28: 2NAD01
A29: 1552 | B29: AZDAD | C29: ABDERRAHMAN | D29: Nador | Y29: Employé | Z29: B | AA29: 45047 | AC29: 33786 | AD29: M | AE29: Mr | AF29: 0 | AG29: 2NAD01
A30: 1565 | B30: BENALI | C30: WASSIM | D30: Nador | Y30: Employé | Z30: B | AA30: 45139 | AC30: 35249 | AD30: M | AE30: Mr | AF30: 0 | AG30: 2NAD01
A31: 1595 | B31: BUYGAYDAN | C31: MOHAMED | D31: Nador | Y31: Employé | Z31: B | AA31: 45293 | AC31: 36718 | AD31: C | AE31: Mr | AF31: 0 | AG31: 2NAD01
A32: 1627 | B32: MOULAY | C32: HAMZA | D32: Nador | Y32: Employé | Z32: B | AA32: 45383 | AC32: 36041 | AD32: C | AE32: Mr | AF32: 0 | AG32: 2NAD01
A33: 324 | B33: EL KADAOUI | C33: HASSAN | D33: Nador | Y33: Maitrise | Z33: 4 | AA33: 32822 | AB33: 45807 | AC33: 23892 | AD33: M | AE33: Mr | AF33: 25 | AG33: 2NAD01
A34: 1673 | B34: CHAOUQUI | C34: MOHAMED | D34: Nador | Y34: Maitrise | Z34: D | AA34: 45659 | AC34: 34686 | AD34: C | AE34: Mr | AF34: 0 | AG34: 2NAD01
A35: 1508 | B35: EL BADMOUSSI | C35: ABDELILAH | D35: Nador | Y35: Employé | Z35: B | AA35: 44896 | AC35: 32579 | AD35: M | AE35: Mr | AF35: 5 | AG35: 2NAD01
A36: 1451 | B36: FEDDAHI | C36: ABDESSAMAD | D36: Nador | Y36: Employé | Z36: C | AA36: 44621 | AC36: 31884 | AD36: M | AE36: Mr | AF36: 5 | AG36: 2NAD01
A37: 1417 | B37: AABKARI | C37: MOUAD | D37: Nador | Y37: Maitrise | Z37: F | AA37: 44515 | AB37: 45740 | AC37: 35130 | AD37: C | AE37: Mr | AF37: 5 | AG37: 2NAD01
A38: 1390 | B38: AKEBI | C38: ABDELGHANI | D38: Nador | Y38: Employé | Z38: B | AA38: 44105 | AC38: 35385 | AD38: C | AE38: Mr | AF38: 5 | AG38: 2NAD01
A39: 957 | B39: SLIMANI | C39: MOURAD | D39: Nador | Y39: Maitrise | Z39: D | AA39: 39264 | AC39: 31068 | AD39: M | AE39: Mr | AF39: 15 | AG39: 2NAD01
A40: 494 | B40: MACHROUT | C40: RACHID | D40: Nador | Y40: Employé | Z40: C | AA40: 35996 | AC40: 26872 | AD40: M | AE40: Mr | AF40: 25 | AG40: 2NAD01
...

Sheet Feuil1
A1: 1 | B1: 2 | C1: 3 | D1: 4 | E1: 5 | F1: 6 | G1: 7 | H1: 8 | I1: 9 | J1: 10 | K1: 11 | L1: 12 | M1: 13 | N1: 14 | O1: 15 | P1: 16 | Q1: 17 | R1: 18 | S1: 19 | T1: 20 | U1: 21 | V1: 22 | W1: 23 | X1: 24 | Y1: 25 | Z1: 26 | AA1: 27 | AB1: 28 | AC1: 29 | AD1: 30 | AE1: 31 | AF1: 32 | AG1: 33 | AH1: 34
A2: Matricule | B2: Nom | C2: Prenom | D2: Lieu de travail | E2: Base | F2: PRIME_REPRESENT | G2: Indemnité transport | H2: Indemnité poste | I2: Prime logement | J2: P logement n logé | K2: P logement logé | L2: P logement famille | M2: Indemnité encadrement | N2: Indemnité panier | O2: Indemnité chaleur | P2: Indemnité salissure | Q2: Indemnité poste douche | R2: Indemnité contre maitre | S2: Indemnité velomoteur | T2: Indemnité dimanche | U2: Prime caisse | V2: Forfait HS | W2: Indemnité compensatrice | X2: Indémnité chef de poste | Y2: Collège | Z2: Echelle | AA2: DEB_CONTRAT | AB2: FIN_CONTRAT | AC2: DT_NAISSANCE | AD2: Famille | AE2: CIVILITE | AF2: Taux Prime ancienneté
A3: 180 | B3: FELIOUNE | C3: MOSTAPHA | D3: Nador | Y3: Maitrise | Z3: 8 | AA3: 30881 | AC3: 23172 | AD3: M | AE3: Mr | AF3: 25 | AG3: 2PRO06
A4: 183 | B4: ASBAI | C4: IDRISS | D4: Nador | Y4: Maitrise | Z4: 5 | AA4: 30888 | AC4: 23417 | AD4: M | AE4: Mr | AF4: 25 | AG4: 2SDN01
A5: 208 | B5: ZARIOUH | C5: FARID | D5: Nador | Y5: Employé | Z5: 10 | AA5: 30942 | AC5: 23437 | AD5: M | AE5: Mr | AF5: 25 | AG5: 2FIB01
A6: 213 | B6: AJJAJI | C6: MOHAMED | D6: Nador | Y6: Maitrise | Z6: 9 | AA6: 30956 | AC6: 23558 | AD6: M | AE6: Mr | AF6: 25 | AG6: 2PRO03
A7: 236 | B7: TAZIOUEN | C7: MUSTAPHA | D7: Nador | Y7: Maitrise | Z7: 5 | AA7: 31292 | AC7: 23480 | AD7: M | AE7: Mr | AF7: 25 | AG7: 2MAI02
A8: 239 | B8: BELHASSANI | C8: OMAR | D8: Nador | Y8: Maitrise | Z8: 6 | AA8: 31348 | AC8: 24093 | AD8: M | AE8: Mr | AF8: 25 | AG8: 2MAI10
A9: 240 | B9: EL HADDIOUI | C9: BENAISSA | D9: Nador | Y9: Employé | Z9: 8 | AA9: 31355 | AC9: 23584 | AD9: M | AE9: Mr | AF9: 25 | AG9: 2MAI03
A10: 242 | B10: ELMADANI | C10: AISSA | D10: Nador | Y10: Employé | Z10: 10 | AA10: 31378 | AC10: 23294 | AD10: M | AE10: Mr | AF10: 25 | AG10: 2DRH09
A11: 249 | B11: ARRAHI | C11: MOUSTAPHA | D11: Nador | Y11: Maitrise | Z11: 5 | AA11: 31425 | AC11: 23233 | AD11: M | AE11: Mr | AF11: 25 | AG11: 2MAI07
A12: 252 | B12: SKALLI | C12: NAOUAL | D12: Nador | Y12: Maitrise | Z12: 5 | AA12: 31455 | AC12: 23642 | AD12: M | AE12: Mme | AF12: 25 | AG12: 2DRH09
A13: 263 | B13: BOUYANZAR | C13: AHMED | D13: Nador | Y13: Maitrise | Z13: 5 | AA13: 31699 | AC13: 23691 | AD13: M | AE13: Mr | AF13: 25 | AG13: 2GAR02
A14: 268 | B14: ABDEL-ILAH | C14: TOUFIK | D14: Nador | Y14: Maitrise | Z14: 6 | AA14: 31769 | AC14: 23464 | AD14: M | AE14: Mr | AF14: 25 | AG14: 2SEC01
... A43: 393 | B43: TALAA | C43: M'HAMMED | D43: Nador | Y43: Maitrise | Z43: 4 | AA43: 34554 | AC43: 25165 | AD43: M | AE43: Mr | AF43: 25 | AG43: 2PRO03
A44: 455 | B44: TAHIRI | C44: ABDELKADER | D44: Nador | Y44: Employé | Z44: C | AA44: 35947 | AC44: 24750 | AD44: C | AE44: Mr | AF44: 20 | AG44: 2PRO05
A45: 456 | B45: ARRAISS | C45: ABDESLAM | D45: Nador | Y45: Employé | Z45: C | AA45: 35947 | AC45: 26344 | AD45: M | AE45: Mr | AF45: 20 | AG45: 2FIB01
A46: 458 | B46: AZIZI | C46: MUSTAPHA | D46: Nador | Y46: Employé | Z46: C | AA46: 35947 | AC46: 26186 | AD46: M | AE46: Mr | AF46: 20 | AG46: 2MAI02
A47: 459 | B47: BEN OTMAN | C47: JAMAL | D47: Nador | Y47: Employé | Z47: C | AA47: 35947 | AC47: 25913 | AD47: M | AE47: Mr | AF47: 20 | AG47: 2SGX01
